2020-02-11 10:22:18,233	Traceback (most recent call last):
  File "/usr/local/lib/python2.7/dist-packages/yandextank/plugins/DataUploader/client.py", line 192, in __make_api_request
    response = self.__send_single_request(request, ids.next(), trace=trace)
  File "/usr/local/lib/python2.7/dist-packages/yandextank/plugins/DataUploader/client.py", line 131, in __send_single_request
    resp = self.session.send(p, timeout=self.connection_timeout)
  File "/usr/local/lib/python2.7/dist-packages/requests/sessions.py", line 646, in send
    r = adapter.send(request, **kwargs)
  File "/usr/local/lib/python2.7/dist-packages/requests/adapters.py", line 498, in send
    raise ConnectionError(err, request=request)
ConnectionError: ('Connection aborted.', BadStatusLine("''",))

2020-02-11 10:22:18,236	Network error, will retry in 10s...
2020-02-11 10:22:30,019	Traceback (most recent call last):
  File "/usr/local/lib/python2.7/dist-packages/yandextank/plugins/DataUploader/client.py", line 192, in __make_api_request
    response = self.__send_single_request(request, ids.next(), trace=trace)
  File "/usr/local/lib/python2.7/dist-packages/yandextank/plugins/DataUploader/client.py", line 131, in __send_single_request
    resp = self.session.send(p, timeout=self.connection_timeout)
  File "/usr/local/lib/python2.7/dist-packages/requests/sessions.py", line 646, in send
    r = adapter.send(request, **kwargs)
  File "/usr/local/lib/python2.7/dist-packages/requests/adapters.py", line 498, in send
    raise ConnectionError(err, request=request)
ConnectionError: ('Connection aborted.', BadStatusLine("''",))

2020-02-11 10:22:30,021	Network error, will retry in 10s...
2020-02-11 10:23:10,569	Traceback (most recent call last):
  File "/usr/local/lib/python2.7/dist-packages/yandextank/plugins/DataUploader/client.py", line 192, in __make_api_request
    response = self.__send_single_request(request, ids.next(), trace=trace)
  File "/usr/local/lib/python2.7/dist-packages/yandextank/plugins/DataUploader/client.py", line 131, in __send_single_request
    resp = self.session.send(p, timeout=self.connection_timeout)
  File "/usr/local/lib/python2.7/dist-packages/requests/sessions.py", line 646, in send
    r = adapter.send(request, **kwargs)
  File "/usr/local/lib/python2.7/dist-packages/requests/adapters.py", line 498, in send
    raise ConnectionError(err, request=request)
ConnectionError: ('Connection aborted.', BadStatusLine("''",))

2020-02-11 10:23:10,570	Network error, will retry in 10s...
2020-02-11 10:23:20,946	Traceback (most recent call last):
  File "/usr/local/lib/python2.7/dist-packages/yandextank/plugins/DataUploader/client.py", line 192, in __make_api_request
    response = self.__send_single_request(request, ids.next(), trace=trace)
  File "/usr/local/lib/python2.7/dist-packages/yandextank/plugins/DataUploader/client.py", line 131, in __send_single_request
    resp = self.session.send(p, timeout=self.connection_timeout)
  File "/usr/local/lib/python2.7/dist-packages/requests/sessions.py", line 646, in send
    r = adapter.send(request, **kwargs)
  File "/usr/local/lib/python2.7/dist-packages/requests/adapters.py", line 498, in send
    raise ConnectionError(err, request=request)
ConnectionError: ('Connection aborted.', BadStatusLine("''",))

2020-02-11 10:23:20,947	Network error, will retry in 10s...
2020-02-11 10:23:31,147	File already exists: /tmp/2020-02-11_10-22-16.084906/phantom_stat_s2U4sU.log
2020-02-11 10:23:31,148	File already exists: /tmp/2020-02-11_10-22-16.084906/answ_wEWfTB.log
2020-02-11 10:23:31,149	File already exists: /tmp/2020-02-11_10-22-16.084906/phantom_BUIrbZ.conf
2020-02-11 10:23:31,151	File already exists: /tmp/2020-02-11_10-22-16.084906/phantom_stdout_stderr_RgmrKD.log
2020-02-11 10:23:31,152	File already exists: /tmp/2020-02-11_10-22-16.084906/phantom_sE9V3d.log
2020-02-11 10:23:31,154	File not found to collect: validation_error.yaml
2020-02-11 10:23:31,164	File already exists: /tmp/2020-02-11_10-22-16.084906/phout_uS0BYw.log
